[2022-02-12 14:11:55,905] {processor.py:163} INFO - Started process (PID=832) to work on /opt/airflow/dags/example_api_to_postgre/api_midway_to_postgres_dag.py
[2022-02-12 14:11:55,907] {processor.py:625} INFO - Processing file /opt/airflow/dags/example_api_to_postgre/api_midway_to_postgres_dag.py for tasks to queue
[2022-02-12 14:11:55,909] {logging_mixin.py:109} INFO - [2022-02-12 14:11:55,908] {dagbag.py:500} INFO - Filling up the DagBag from /opt/airflow/dags/example_api_to_postgre/api_midway_to_postgres_dag.py
[2022-02-12 14:11:55,967] {logging_mixin.py:109} INFO - [2022-02-12 14:11:55,960] {dagbag.py:334} ERROR - Failed to import: /opt/airflow/dags/example_api_to_postgre/api_midway_to_postgres_dag.py
Traceback (most recent call last):
  File "/home/airflow/.local/lib/python3.7/site-packages/airflow/models/dagbag.py", line 331, in _load_modules_from_file
    loader.exec_module(new_module)
  File "<frozen importlib._bootstrap_external>", line 728, in exec_module
  File "<frozen importlib._bootstrap>", line 219, in _call_with_frames_removed
  File "/opt/airflow/dags/example_api_to_postgre/api_midway_to_postgres_dag.py", line 25, in <module>
    '--connection %s' % Variable.get("data_dev_connection")
  File "/home/airflow/.local/lib/python3.7/site-packages/airflow/models/variable.py", line 140, in get
    raise KeyError(f'Variable {key} does not exist')
KeyError: 'Variable data_dev_connection does not exist'
[2022-02-12 14:11:55,975] {processor.py:639} WARNING - No viable dags retrieved from /opt/airflow/dags/example_api_to_postgre/api_midway_to_postgres_dag.py
[2022-02-12 14:11:55,993] {processor.py:171} INFO - Processing /opt/airflow/dags/example_api_to_postgre/api_midway_to_postgres_dag.py took 0.092 seconds
[2022-02-12 14:12:26,068] {processor.py:163} INFO - Started process (PID=889) to work on /opt/airflow/dags/example_api_to_postgre/api_midway_to_postgres_dag.py
[2022-02-12 14:12:26,070] {processor.py:625} INFO - Processing file /opt/airflow/dags/example_api_to_postgre/api_midway_to_postgres_dag.py for tasks to queue
[2022-02-12 14:12:26,072] {logging_mixin.py:109} INFO - [2022-02-12 14:12:26,072] {dagbag.py:500} INFO - Filling up the DagBag from /opt/airflow/dags/example_api_to_postgre/api_midway_to_postgres_dag.py
[2022-02-12 14:12:26,107] {logging_mixin.py:109} INFO - [2022-02-12 14:12:26,106] {dagbag.py:334} ERROR - Failed to import: /opt/airflow/dags/example_api_to_postgre/api_midway_to_postgres_dag.py
Traceback (most recent call last):
  File "/home/airflow/.local/lib/python3.7/site-packages/airflow/models/dagbag.py", line 331, in _load_modules_from_file
    loader.exec_module(new_module)
  File "<frozen importlib._bootstrap_external>", line 728, in exec_module
  File "<frozen importlib._bootstrap>", line 219, in _call_with_frames_removed
  File "/opt/airflow/dags/example_api_to_postgre/api_midway_to_postgres_dag.py", line 25, in <module>
    '--connection %s' % Variable.get("data_dev_connection")
  File "/home/airflow/.local/lib/python3.7/site-packages/airflow/models/variable.py", line 140, in get
    raise KeyError(f'Variable {key} does not exist')
KeyError: 'Variable data_dev_connection does not exist'
[2022-02-12 14:12:26,113] {processor.py:639} WARNING - No viable dags retrieved from /opt/airflow/dags/example_api_to_postgre/api_midway_to_postgres_dag.py
[2022-02-12 14:12:26,120] {processor.py:171} INFO - Processing /opt/airflow/dags/example_api_to_postgre/api_midway_to_postgres_dag.py took 0.057 seconds
[2022-02-12 14:12:56,716] {processor.py:163} INFO - Started process (PID=934) to work on /opt/airflow/dags/example_api_to_postgre/api_midway_to_postgres_dag.py
[2022-02-12 14:12:56,718] {processor.py:625} INFO - Processing file /opt/airflow/dags/example_api_to_postgre/api_midway_to_postgres_dag.py for tasks to queue
[2022-02-12 14:12:56,719] {logging_mixin.py:109} INFO - [2022-02-12 14:12:56,719] {dagbag.py:500} INFO - Filling up the DagBag from /opt/airflow/dags/example_api_to_postgre/api_midway_to_postgres_dag.py
[2022-02-12 14:12:56,755] {logging_mixin.py:109} INFO - [2022-02-12 14:12:56,752] {dagbag.py:334} ERROR - Failed to import: /opt/airflow/dags/example_api_to_postgre/api_midway_to_postgres_dag.py
Traceback (most recent call last):
  File "/home/airflow/.local/lib/python3.7/site-packages/airflow/models/dagbag.py", line 331, in _load_modules_from_file
    loader.exec_module(new_module)
  File "<frozen importlib._bootstrap_external>", line 728, in exec_module
  File "<frozen importlib._bootstrap>", line 219, in _call_with_frames_removed
  File "/opt/airflow/dags/example_api_to_postgre/api_midway_to_postgres_dag.py", line 25, in <module>
    '--connection %s' % Variable.get("data_dev_connection")
  File "/home/airflow/.local/lib/python3.7/site-packages/airflow/models/variable.py", line 140, in get
    raise KeyError(f'Variable {key} does not exist')
KeyError: 'Variable data_dev_connection does not exist'
[2022-02-12 14:12:56,762] {processor.py:639} WARNING - No viable dags retrieved from /opt/airflow/dags/example_api_to_postgre/api_midway_to_postgres_dag.py
[2022-02-12 14:12:56,772] {processor.py:171} INFO - Processing /opt/airflow/dags/example_api_to_postgre/api_midway_to_postgres_dag.py took 0.059 seconds
[2022-02-12 14:13:27,304] {processor.py:163} INFO - Started process (PID=989) to work on /opt/airflow/dags/example_api_to_postgre/api_midway_to_postgres_dag.py
[2022-02-12 14:13:27,307] {processor.py:625} INFO - Processing file /opt/airflow/dags/example_api_to_postgre/api_midway_to_postgres_dag.py for tasks to queue
[2022-02-12 14:13:27,309] {logging_mixin.py:109} INFO - [2022-02-12 14:13:27,309] {dagbag.py:500} INFO - Filling up the DagBag from /opt/airflow/dags/example_api_to_postgre/api_midway_to_postgres_dag.py
[2022-02-12 14:13:27,356] {logging_mixin.py:109} INFO - [2022-02-12 14:13:27,352] {dagbag.py:334} ERROR - Failed to import: /opt/airflow/dags/example_api_to_postgre/api_midway_to_postgres_dag.py
Traceback (most recent call last):
  File "/home/airflow/.local/lib/python3.7/site-packages/airflow/models/dagbag.py", line 331, in _load_modules_from_file
    loader.exec_module(new_module)
  File "<frozen importlib._bootstrap_external>", line 728, in exec_module
  File "<frozen importlib._bootstrap>", line 219, in _call_with_frames_removed
  File "/opt/airflow/dags/example_api_to_postgre/api_midway_to_postgres_dag.py", line 25, in <module>
    '--connection %s' % Variable.get("data_dev_connection")
  File "/home/airflow/.local/lib/python3.7/site-packages/airflow/models/variable.py", line 140, in get
    raise KeyError(f'Variable {key} does not exist')
KeyError: 'Variable data_dev_connection does not exist'
[2022-02-12 14:13:27,364] {processor.py:639} WARNING - No viable dags retrieved from /opt/airflow/dags/example_api_to_postgre/api_midway_to_postgres_dag.py
[2022-02-12 14:13:27,375] {processor.py:171} INFO - Processing /opt/airflow/dags/example_api_to_postgre/api_midway_to_postgres_dag.py took 0.076 seconds
[2022-02-12 14:13:57,715] {processor.py:163} INFO - Started process (PID=1032) to work on /opt/airflow/dags/example_api_to_postgre/api_midway_to_postgres_dag.py
[2022-02-12 14:13:57,718] {processor.py:625} INFO - Processing file /opt/airflow/dags/example_api_to_postgre/api_midway_to_postgres_dag.py for tasks to queue
[2022-02-12 14:13:57,720] {logging_mixin.py:109} INFO - [2022-02-12 14:13:57,719] {dagbag.py:500} INFO - Filling up the DagBag from /opt/airflow/dags/example_api_to_postgre/api_midway_to_postgres_dag.py
[2022-02-12 14:13:57,767] {logging_mixin.py:109} INFO - [2022-02-12 14:13:57,765] {dagbag.py:334} ERROR - Failed to import: /opt/airflow/dags/example_api_to_postgre/api_midway_to_postgres_dag.py
Traceback (most recent call last):
  File "/home/airflow/.local/lib/python3.7/site-packages/airflow/models/dagbag.py", line 331, in _load_modules_from_file
    loader.exec_module(new_module)
  File "<frozen importlib._bootstrap_external>", line 728, in exec_module
  File "<frozen importlib._bootstrap>", line 219, in _call_with_frames_removed
  File "/opt/airflow/dags/example_api_to_postgre/api_midway_to_postgres_dag.py", line 25, in <module>
    '--connection %s' % Variable.get("data_dev_connection")
  File "/home/airflow/.local/lib/python3.7/site-packages/airflow/models/variable.py", line 140, in get
    raise KeyError(f'Variable {key} does not exist')
KeyError: 'Variable data_dev_connection does not exist'
[2022-02-12 14:13:57,777] {processor.py:639} WARNING - No viable dags retrieved from /opt/airflow/dags/example_api_to_postgre/api_midway_to_postgres_dag.py
[2022-02-12 14:13:57,785] {processor.py:171} INFO - Processing /opt/airflow/dags/example_api_to_postgre/api_midway_to_postgres_dag.py took 0.075 seconds
[2022-02-12 14:14:28,783] {processor.py:163} INFO - Started process (PID=1075) to work on /opt/airflow/dags/example_api_to_postgre/api_midway_to_postgres_dag.py
[2022-02-12 14:14:28,786] {processor.py:625} INFO - Processing file /opt/airflow/dags/example_api_to_postgre/api_midway_to_postgres_dag.py for tasks to queue
[2022-02-12 14:14:28,791] {logging_mixin.py:109} INFO - [2022-02-12 14:14:28,790] {dagbag.py:500} INFO - Filling up the DagBag from /opt/airflow/dags/example_api_to_postgre/api_midway_to_postgres_dag.py
[2022-02-12 14:14:28,865] {logging_mixin.py:109} INFO - [2022-02-12 14:14:28,859] {dagbag.py:334} ERROR - Failed to import: /opt/airflow/dags/example_api_to_postgre/api_midway_to_postgres_dag.py
Traceback (most recent call last):
  File "/home/airflow/.local/lib/python3.7/site-packages/airflow/models/dagbag.py", line 331, in _load_modules_from_file
    loader.exec_module(new_module)
  File "<frozen importlib._bootstrap_external>", line 728, in exec_module
  File "<frozen importlib._bootstrap>", line 219, in _call_with_frames_removed
  File "/opt/airflow/dags/example_api_to_postgre/api_midway_to_postgres_dag.py", line 25, in <module>
    '--connection %s' % Variable.get("data_dev_connection")
  File "/home/airflow/.local/lib/python3.7/site-packages/airflow/models/variable.py", line 140, in get
    raise KeyError(f'Variable {key} does not exist')
KeyError: 'Variable data_dev_connection does not exist'
[2022-02-12 14:14:28,878] {processor.py:639} WARNING - No viable dags retrieved from /opt/airflow/dags/example_api_to_postgre/api_midway_to_postgres_dag.py
[2022-02-12 14:14:28,890] {processor.py:171} INFO - Processing /opt/airflow/dags/example_api_to_postgre/api_midway_to_postgres_dag.py took 0.117 seconds
[2022-02-12 14:14:59,112] {processor.py:163} INFO - Started process (PID=1128) to work on /opt/airflow/dags/example_api_to_postgre/api_midway_to_postgres_dag.py
[2022-02-12 14:14:59,115] {processor.py:625} INFO - Processing file /opt/airflow/dags/example_api_to_postgre/api_midway_to_postgres_dag.py for tasks to queue
[2022-02-12 14:14:59,117] {logging_mixin.py:109} INFO - [2022-02-12 14:14:59,117] {dagbag.py:500} INFO - Filling up the DagBag from /opt/airflow/dags/example_api_to_postgre/api_midway_to_postgres_dag.py
[2022-02-12 14:14:59,162] {logging_mixin.py:109} INFO - [2022-02-12 14:14:59,159] {dagbag.py:334} ERROR - Failed to import: /opt/airflow/dags/example_api_to_postgre/api_midway_to_postgres_dag.py
Traceback (most recent call last):
  File "/home/airflow/.local/lib/python3.7/site-packages/airflow/models/dagbag.py", line 331, in _load_modules_from_file
    loader.exec_module(new_module)
  File "<frozen importlib._bootstrap_external>", line 728, in exec_module
  File "<frozen importlib._bootstrap>", line 219, in _call_with_frames_removed
  File "/opt/airflow/dags/example_api_to_postgre/api_midway_to_postgres_dag.py", line 25, in <module>
    '--connection %s' % Variable.get("data_dev_connection")
  File "/home/airflow/.local/lib/python3.7/site-packages/airflow/models/variable.py", line 140, in get
    raise KeyError(f'Variable {key} does not exist')
KeyError: 'Variable data_dev_connection does not exist'
[2022-02-12 14:14:59,172] {processor.py:639} WARNING - No viable dags retrieved from /opt/airflow/dags/example_api_to_postgre/api_midway_to_postgres_dag.py
[2022-02-12 14:14:59,188] {processor.py:171} INFO - Processing /opt/airflow/dags/example_api_to_postgre/api_midway_to_postgres_dag.py took 0.082 seconds
[2022-02-12 14:15:29,300] {processor.py:163} INFO - Started process (PID=1172) to work on /opt/airflow/dags/example_api_to_postgre/api_midway_to_postgres_dag.py
[2022-02-12 14:15:29,305] {processor.py:625} INFO - Processing file /opt/airflow/dags/example_api_to_postgre/api_midway_to_postgres_dag.py for tasks to queue
[2022-02-12 14:15:29,307] {logging_mixin.py:109} INFO - [2022-02-12 14:15:29,307] {dagbag.py:500} INFO - Filling up the DagBag from /opt/airflow/dags/example_api_to_postgre/api_midway_to_postgres_dag.py
[2022-02-12 14:15:29,344] {logging_mixin.py:109} INFO - [2022-02-12 14:15:29,342] {dagbag.py:334} ERROR - Failed to import: /opt/airflow/dags/example_api_to_postgre/api_midway_to_postgres_dag.py
Traceback (most recent call last):
  File "/home/airflow/.local/lib/python3.7/site-packages/airflow/models/dagbag.py", line 331, in _load_modules_from_file
    loader.exec_module(new_module)
  File "<frozen importlib._bootstrap_external>", line 728, in exec_module
  File "<frozen importlib._bootstrap>", line 219, in _call_with_frames_removed
  File "/opt/airflow/dags/example_api_to_postgre/api_midway_to_postgres_dag.py", line 25, in <module>
    '--connection %s' % Variable.get("data_dev_connection")
  File "/home/airflow/.local/lib/python3.7/site-packages/airflow/models/variable.py", line 140, in get
    raise KeyError(f'Variable {key} does not exist')
KeyError: 'Variable data_dev_connection does not exist'
[2022-02-12 14:15:29,349] {processor.py:639} WARNING - No viable dags retrieved from /opt/airflow/dags/example_api_to_postgre/api_midway_to_postgres_dag.py
[2022-02-12 14:15:29,357] {processor.py:171} INFO - Processing /opt/airflow/dags/example_api_to_postgre/api_midway_to_postgres_dag.py took 0.062 seconds
[2022-02-12 14:16:00,332] {processor.py:163} INFO - Started process (PID=1225) to work on /opt/airflow/dags/example_api_to_postgre/api_midway_to_postgres_dag.py
[2022-02-12 14:16:00,336] {processor.py:625} INFO - Processing file /opt/airflow/dags/example_api_to_postgre/api_midway_to_postgres_dag.py for tasks to queue
[2022-02-12 14:16:00,338] {logging_mixin.py:109} INFO - [2022-02-12 14:16:00,338] {dagbag.py:500} INFO - Filling up the DagBag from /opt/airflow/dags/example_api_to_postgre/api_midway_to_postgres_dag.py
[2022-02-12 14:16:00,373] {logging_mixin.py:109} INFO - [2022-02-12 14:16:00,371] {dagbag.py:334} ERROR - Failed to import: /opt/airflow/dags/example_api_to_postgre/api_midway_to_postgres_dag.py
Traceback (most recent call last):
  File "/home/airflow/.local/lib/python3.7/site-packages/airflow/models/dagbag.py", line 331, in _load_modules_from_file
    loader.exec_module(new_module)
  File "<frozen importlib._bootstrap_external>", line 728, in exec_module
  File "<frozen importlib._bootstrap>", line 219, in _call_with_frames_removed
  File "/opt/airflow/dags/example_api_to_postgre/api_midway_to_postgres_dag.py", line 25, in <module>
    '--connection %s' % Variable.get("data_dev_connection")
  File "/home/airflow/.local/lib/python3.7/site-packages/airflow/models/variable.py", line 140, in get
    raise KeyError(f'Variable {key} does not exist')
KeyError: 'Variable data_dev_connection does not exist'
[2022-02-12 14:16:00,380] {processor.py:639} WARNING - No viable dags retrieved from /opt/airflow/dags/example_api_to_postgre/api_midway_to_postgres_dag.py
[2022-02-12 14:16:00,386] {processor.py:171} INFO - Processing /opt/airflow/dags/example_api_to_postgre/api_midway_to_postgres_dag.py took 0.059 seconds
[2022-02-12 14:16:31,260] {processor.py:163} INFO - Started process (PID=1271) to work on /opt/airflow/dags/example_api_to_postgre/api_midway_to_postgres_dag.py
[2022-02-12 14:16:31,262] {processor.py:625} INFO - Processing file /opt/airflow/dags/example_api_to_postgre/api_midway_to_postgres_dag.py for tasks to queue
[2022-02-12 14:16:31,264] {logging_mixin.py:109} INFO - [2022-02-12 14:16:31,264] {dagbag.py:500} INFO - Filling up the DagBag from /opt/airflow/dags/example_api_to_postgre/api_midway_to_postgres_dag.py
[2022-02-12 14:16:31,302] {logging_mixin.py:109} INFO - [2022-02-12 14:16:31,300] {dagbag.py:334} ERROR - Failed to import: /opt/airflow/dags/example_api_to_postgre/api_midway_to_postgres_dag.py
Traceback (most recent call last):
  File "/home/airflow/.local/lib/python3.7/site-packages/airflow/models/dagbag.py", line 331, in _load_modules_from_file
    loader.exec_module(new_module)
  File "<frozen importlib._bootstrap_external>", line 728, in exec_module
  File "<frozen importlib._bootstrap>", line 219, in _call_with_frames_removed
  File "/opt/airflow/dags/example_api_to_postgre/api_midway_to_postgres_dag.py", line 25, in <module>
    '--connection %s' % Variable.get("data_dev_connection")
  File "/home/airflow/.local/lib/python3.7/site-packages/airflow/models/variable.py", line 140, in get
    raise KeyError(f'Variable {key} does not exist')
KeyError: 'Variable data_dev_connection does not exist'
[2022-02-12 14:16:31,309] {processor.py:639} WARNING - No viable dags retrieved from /opt/airflow/dags/example_api_to_postgre/api_midway_to_postgres_dag.py
[2022-02-12 14:16:31,319] {processor.py:171} INFO - Processing /opt/airflow/dags/example_api_to_postgre/api_midway_to_postgres_dag.py took 0.063 seconds
[2022-02-12 14:17:01,795] {processor.py:163} INFO - Started process (PID=1309) to work on /opt/airflow/dags/example_api_to_postgre/api_midway_to_postgres_dag.py
[2022-02-12 14:17:01,798] {processor.py:625} INFO - Processing file /opt/airflow/dags/example_api_to_postgre/api_midway_to_postgres_dag.py for tasks to queue
[2022-02-12 14:17:01,800] {logging_mixin.py:109} INFO - [2022-02-12 14:17:01,799] {dagbag.py:500} INFO - Filling up the DagBag from /opt/airflow/dags/example_api_to_postgre/api_midway_to_postgres_dag.py
[2022-02-12 14:17:01,844] {logging_mixin.py:109} INFO - [2022-02-12 14:17:01,842] {dagbag.py:334} ERROR - Failed to import: /opt/airflow/dags/example_api_to_postgre/api_midway_to_postgres_dag.py
Traceback (most recent call last):
  File "/home/airflow/.local/lib/python3.7/site-packages/airflow/models/dagbag.py", line 331, in _load_modules_from_file
    loader.exec_module(new_module)
  File "<frozen importlib._bootstrap_external>", line 728, in exec_module
  File "<frozen importlib._bootstrap>", line 219, in _call_with_frames_removed
  File "/opt/airflow/dags/example_api_to_postgre/api_midway_to_postgres_dag.py", line 25, in <module>
    '--connection %s' % Variable.get("data_dev_connection")
  File "/home/airflow/.local/lib/python3.7/site-packages/airflow/models/variable.py", line 140, in get
    raise KeyError(f'Variable {key} does not exist')
KeyError: 'Variable data_dev_connection does not exist'
[2022-02-12 14:17:01,850] {processor.py:639} WARNING - No viable dags retrieved from /opt/airflow/dags/example_api_to_postgre/api_midway_to_postgres_dag.py
[2022-02-12 14:17:01,858] {processor.py:171} INFO - Processing /opt/airflow/dags/example_api_to_postgre/api_midway_to_postgres_dag.py took 0.067 seconds
[2022-02-12 14:17:31,892] {processor.py:163} INFO - Started process (PID=1353) to work on /opt/airflow/dags/example_api_to_postgre/api_midway_to_postgres_dag.py
[2022-02-12 14:17:31,895] {processor.py:625} INFO - Processing file /opt/airflow/dags/example_api_to_postgre/api_midway_to_postgres_dag.py for tasks to queue
[2022-02-12 14:17:31,896] {logging_mixin.py:109} INFO - [2022-02-12 14:17:31,896] {dagbag.py:500} INFO - Filling up the DagBag from /opt/airflow/dags/example_api_to_postgre/api_midway_to_postgres_dag.py
[2022-02-12 14:17:31,931] {logging_mixin.py:109} INFO - [2022-02-12 14:17:31,929] {dagbag.py:334} ERROR - Failed to import: /opt/airflow/dags/example_api_to_postgre/api_midway_to_postgres_dag.py
Traceback (most recent call last):
  File "/home/airflow/.local/lib/python3.7/site-packages/airflow/models/dagbag.py", line 331, in _load_modules_from_file
    loader.exec_module(new_module)
  File "<frozen importlib._bootstrap_external>", line 728, in exec_module
  File "<frozen importlib._bootstrap>", line 219, in _call_with_frames_removed
  File "/opt/airflow/dags/example_api_to_postgre/api_midway_to_postgres_dag.py", line 25, in <module>
    '--connection %s' % Variable.get("data_dev_connection")
  File "/home/airflow/.local/lib/python3.7/site-packages/airflow/models/variable.py", line 140, in get
    raise KeyError(f'Variable {key} does not exist')
KeyError: 'Variable data_dev_connection does not exist'
[2022-02-12 14:17:31,937] {processor.py:639} WARNING - No viable dags retrieved from /opt/airflow/dags/example_api_to_postgre/api_midway_to_postgres_dag.py
[2022-02-12 14:17:31,944] {processor.py:171} INFO - Processing /opt/airflow/dags/example_api_to_postgre/api_midway_to_postgres_dag.py took 0.057 seconds
[2022-02-12 14:18:02,073] {processor.py:163} INFO - Started process (PID=1408) to work on /opt/airflow/dags/example_api_to_postgre/api_midway_to_postgres_dag.py
[2022-02-12 14:18:02,076] {processor.py:625} INFO - Processing file /opt/airflow/dags/example_api_to_postgre/api_midway_to_postgres_dag.py for tasks to queue
[2022-02-12 14:18:02,078] {logging_mixin.py:109} INFO - [2022-02-12 14:18:02,077] {dagbag.py:500} INFO - Filling up the DagBag from /opt/airflow/dags/example_api_to_postgre/api_midway_to_postgres_dag.py
[2022-02-12 14:18:02,123] {logging_mixin.py:109} INFO - [2022-02-12 14:18:02,120] {dagbag.py:334} ERROR - Failed to import: /opt/airflow/dags/example_api_to_postgre/api_midway_to_postgres_dag.py
Traceback (most recent call last):
  File "/home/airflow/.local/lib/python3.7/site-packages/airflow/models/dagbag.py", line 331, in _load_modules_from_file
    loader.exec_module(new_module)
  File "<frozen importlib._bootstrap_external>", line 728, in exec_module
  File "<frozen importlib._bootstrap>", line 219, in _call_with_frames_removed
  File "/opt/airflow/dags/example_api_to_postgre/api_midway_to_postgres_dag.py", line 25, in <module>
    '--connection %s' % Variable.get("data_dev_connection")
  File "/home/airflow/.local/lib/python3.7/site-packages/airflow/models/variable.py", line 140, in get
    raise KeyError(f'Variable {key} does not exist')
KeyError: 'Variable data_dev_connection does not exist'
[2022-02-12 14:18:02,131] {processor.py:639} WARNING - No viable dags retrieved from /opt/airflow/dags/example_api_to_postgre/api_midway_to_postgres_dag.py
[2022-02-12 14:18:02,140] {processor.py:171} INFO - Processing /opt/airflow/dags/example_api_to_postgre/api_midway_to_postgres_dag.py took 0.071 seconds
[2022-02-12 14:18:32,421] {processor.py:163} INFO - Started process (PID=1453) to work on /opt/airflow/dags/example_api_to_postgre/api_midway_to_postgres_dag.py
[2022-02-12 14:18:32,424] {processor.py:625} INFO - Processing file /opt/airflow/dags/example_api_to_postgre/api_midway_to_postgres_dag.py for tasks to queue
[2022-02-12 14:18:32,425] {logging_mixin.py:109} INFO - [2022-02-12 14:18:32,425] {dagbag.py:500} INFO - Filling up the DagBag from /opt/airflow/dags/example_api_to_postgre/api_midway_to_postgres_dag.py
[2022-02-12 14:18:32,472] {logging_mixin.py:109} INFO - [2022-02-12 14:18:32,468] {dagbag.py:334} ERROR - Failed to import: /opt/airflow/dags/example_api_to_postgre/api_midway_to_postgres_dag.py
Traceback (most recent call last):
  File "/home/airflow/.local/lib/python3.7/site-packages/airflow/models/dagbag.py", line 331, in _load_modules_from_file
    loader.exec_module(new_module)
  File "<frozen importlib._bootstrap_external>", line 728, in exec_module
  File "<frozen importlib._bootstrap>", line 219, in _call_with_frames_removed
  File "/opt/airflow/dags/example_api_to_postgre/api_midway_to_postgres_dag.py", line 25, in <module>
    '--connection %s' % Variable.get("data_dev_connection")
  File "/home/airflow/.local/lib/python3.7/site-packages/airflow/models/variable.py", line 140, in get
    raise KeyError(f'Variable {key} does not exist')
KeyError: 'Variable data_dev_connection does not exist'
[2022-02-12 14:18:32,489] {processor.py:639} WARNING - No viable dags retrieved from /opt/airflow/dags/example_api_to_postgre/api_midway_to_postgres_dag.py
[2022-02-12 14:18:32,505] {processor.py:171} INFO - Processing /opt/airflow/dags/example_api_to_postgre/api_midway_to_postgres_dag.py took 0.088 seconds
[2022-02-12 14:19:02,810] {processor.py:163} INFO - Started process (PID=1508) to work on /opt/airflow/dags/example_api_to_postgre/api_midway_to_postgres_dag.py
[2022-02-12 14:19:02,811] {processor.py:625} INFO - Processing file /opt/airflow/dags/example_api_to_postgre/api_midway_to_postgres_dag.py for tasks to queue
[2022-02-12 14:19:02,814] {logging_mixin.py:109} INFO - [2022-02-12 14:19:02,814] {dagbag.py:500} INFO - Filling up the DagBag from /opt/airflow/dags/example_api_to_postgre/api_midway_to_postgres_dag.py
[2022-02-12 14:19:02,861] {logging_mixin.py:109} INFO - [2022-02-12 14:19:02,859] {dagbag.py:334} ERROR - Failed to import: /opt/airflow/dags/example_api_to_postgre/api_midway_to_postgres_dag.py
Traceback (most recent call last):
  File "/home/airflow/.local/lib/python3.7/site-packages/airflow/models/dagbag.py", line 331, in _load_modules_from_file
    loader.exec_module(new_module)
  File "<frozen importlib._bootstrap_external>", line 728, in exec_module
  File "<frozen importlib._bootstrap>", line 219, in _call_with_frames_removed
  File "/opt/airflow/dags/example_api_to_postgre/api_midway_to_postgres_dag.py", line 25, in <module>
    '--connection %s' % Variable.get("data_dev_connection")
  File "/home/airflow/.local/lib/python3.7/site-packages/airflow/models/variable.py", line 140, in get
    raise KeyError(f'Variable {key} does not exist')
KeyError: 'Variable data_dev_connection does not exist'
[2022-02-12 14:19:02,869] {processor.py:639} WARNING - No viable dags retrieved from /opt/airflow/dags/example_api_to_postgre/api_midway_to_postgres_dag.py
[2022-02-12 14:19:02,877] {processor.py:171} INFO - Processing /opt/airflow/dags/example_api_to_postgre/api_midway_to_postgres_dag.py took 0.071 seconds
[2022-02-12 14:19:32,974] {processor.py:163} INFO - Started process (PID=1551) to work on /opt/airflow/dags/example_api_to_postgre/api_midway_to_postgres_dag.py
[2022-02-12 14:19:32,976] {processor.py:625} INFO - Processing file /opt/airflow/dags/example_api_to_postgre/api_midway_to_postgres_dag.py for tasks to queue
[2022-02-12 14:19:32,978] {logging_mixin.py:109} INFO - [2022-02-12 14:19:32,978] {dagbag.py:500} INFO - Filling up the DagBag from /opt/airflow/dags/example_api_to_postgre/api_midway_to_postgres_dag.py
[2022-02-12 14:19:33,016] {logging_mixin.py:109} INFO - [2022-02-12 14:19:33,014] {dagbag.py:334} ERROR - Failed to import: /opt/airflow/dags/example_api_to_postgre/api_midway_to_postgres_dag.py
Traceback (most recent call last):
  File "/home/airflow/.local/lib/python3.7/site-packages/airflow/models/dagbag.py", line 331, in _load_modules_from_file
    loader.exec_module(new_module)
  File "<frozen importlib._bootstrap_external>", line 728, in exec_module
  File "<frozen importlib._bootstrap>", line 219, in _call_with_frames_removed
  File "/opt/airflow/dags/example_api_to_postgre/api_midway_to_postgres_dag.py", line 25, in <module>
    '--connection %s' % Variable.get("data_dev_connection")
  File "/home/airflow/.local/lib/python3.7/site-packages/airflow/models/variable.py", line 140, in get
    raise KeyError(f'Variable {key} does not exist')
KeyError: 'Variable data_dev_connection does not exist'
[2022-02-12 14:19:33,023] {processor.py:639} WARNING - No viable dags retrieved from /opt/airflow/dags/example_api_to_postgre/api_midway_to_postgres_dag.py
[2022-02-12 14:19:33,031] {processor.py:171} INFO - Processing /opt/airflow/dags/example_api_to_postgre/api_midway_to_postgres_dag.py took 0.062 seconds
[2022-02-12 14:20:03,711] {processor.py:163} INFO - Started process (PID=1603) to work on /opt/airflow/dags/example_api_to_postgre/api_midway_to_postgres_dag.py
[2022-02-12 14:20:03,713] {processor.py:625} INFO - Processing file /opt/airflow/dags/example_api_to_postgre/api_midway_to_postgres_dag.py for tasks to queue
[2022-02-12 14:20:03,714] {logging_mixin.py:109} INFO - [2022-02-12 14:20:03,714] {dagbag.py:500} INFO - Filling up the DagBag from /opt/airflow/dags/example_api_to_postgre/api_midway_to_postgres_dag.py
[2022-02-12 14:20:03,749] {logging_mixin.py:109} INFO - [2022-02-12 14:20:03,748] {dagbag.py:334} ERROR - Failed to import: /opt/airflow/dags/example_api_to_postgre/api_midway_to_postgres_dag.py
Traceback (most recent call last):
  File "/home/airflow/.local/lib/python3.7/site-packages/airflow/models/dagbag.py", line 331, in _load_modules_from_file
    loader.exec_module(new_module)
  File "<frozen importlib._bootstrap_external>", line 728, in exec_module
  File "<frozen importlib._bootstrap>", line 219, in _call_with_frames_removed
  File "/opt/airflow/dags/example_api_to_postgre/api_midway_to_postgres_dag.py", line 25, in <module>
    '--connection %s' % Variable.get("data_dev_connection")
  File "/home/airflow/.local/lib/python3.7/site-packages/airflow/models/variable.py", line 140, in get
    raise KeyError(f'Variable {key} does not exist')
KeyError: 'Variable data_dev_connection does not exist'
[2022-02-12 14:20:03,757] {processor.py:639} WARNING - No viable dags retrieved from /opt/airflow/dags/example_api_to_postgre/api_midway_to_postgres_dag.py
[2022-02-12 14:20:03,764] {processor.py:171} INFO - Processing /opt/airflow/dags/example_api_to_postgre/api_midway_to_postgres_dag.py took 0.056 seconds
[2022-02-12 14:20:33,850] {processor.py:163} INFO - Started process (PID=1647) to work on /opt/airflow/dags/example_api_to_postgre/api_midway_to_postgres_dag.py
[2022-02-12 14:20:33,853] {processor.py:625} INFO - Processing file /opt/airflow/dags/example_api_to_postgre/api_midway_to_postgres_dag.py for tasks to queue
[2022-02-12 14:20:33,855] {logging_mixin.py:109} INFO - [2022-02-12 14:20:33,854] {dagbag.py:500} INFO - Filling up the DagBag from /opt/airflow/dags/example_api_to_postgre/api_midway_to_postgres_dag.py
[2022-02-12 14:20:33,889] {logging_mixin.py:109} INFO - [2022-02-12 14:20:33,887] {dagbag.py:334} ERROR - Failed to import: /opt/airflow/dags/example_api_to_postgre/api_midway_to_postgres_dag.py
Traceback (most recent call last):
  File "/home/airflow/.local/lib/python3.7/site-packages/airflow/models/dagbag.py", line 331, in _load_modules_from_file
    loader.exec_module(new_module)
  File "<frozen importlib._bootstrap_external>", line 728, in exec_module
  File "<frozen importlib._bootstrap>", line 219, in _call_with_frames_removed
  File "/opt/airflow/dags/example_api_to_postgre/api_midway_to_postgres_dag.py", line 25, in <module>
    '--connection %s' % Variable.get("data_dev_connection")
  File "/home/airflow/.local/lib/python3.7/site-packages/airflow/models/variable.py", line 140, in get
    raise KeyError(f'Variable {key} does not exist')
KeyError: 'Variable data_dev_connection does not exist'
[2022-02-12 14:20:33,894] {processor.py:639} WARNING - No viable dags retrieved from /opt/airflow/dags/example_api_to_postgre/api_midway_to_postgres_dag.py
[2022-02-12 14:20:33,902] {processor.py:171} INFO - Processing /opt/airflow/dags/example_api_to_postgre/api_midway_to_postgres_dag.py took 0.055 seconds
[2022-02-12 14:21:04,611] {processor.py:163} INFO - Started process (PID=1701) to work on /opt/airflow/dags/example_api_to_postgre/api_midway_to_postgres_dag.py
[2022-02-12 14:21:04,614] {processor.py:625} INFO - Processing file /opt/airflow/dags/example_api_to_postgre/api_midway_to_postgres_dag.py for tasks to queue
[2022-02-12 14:21:04,615] {logging_mixin.py:109} INFO - [2022-02-12 14:21:04,615] {dagbag.py:500} INFO - Filling up the DagBag from /opt/airflow/dags/example_api_to_postgre/api_midway_to_postgres_dag.py
[2022-02-12 14:21:04,651] {logging_mixin.py:109} INFO - [2022-02-12 14:21:04,649] {dagbag.py:334} ERROR - Failed to import: /opt/airflow/dags/example_api_to_postgre/api_midway_to_postgres_dag.py
Traceback (most recent call last):
  File "/home/airflow/.local/lib/python3.7/site-packages/airflow/models/dagbag.py", line 331, in _load_modules_from_file
    loader.exec_module(new_module)
  File "<frozen importlib._bootstrap_external>", line 728, in exec_module
  File "<frozen importlib._bootstrap>", line 219, in _call_with_frames_removed
  File "/opt/airflow/dags/example_api_to_postgre/api_midway_to_postgres_dag.py", line 25, in <module>
    '--connection %s' % Variable.get("data_dev_connection")
  File "/home/airflow/.local/lib/python3.7/site-packages/airflow/models/variable.py", line 140, in get
    raise KeyError(f'Variable {key} does not exist')
KeyError: 'Variable data_dev_connection does not exist'
[2022-02-12 14:21:04,658] {processor.py:639} WARNING - No viable dags retrieved from /opt/airflow/dags/example_api_to_postgre/api_midway_to_postgres_dag.py
[2022-02-12 14:21:04,665] {processor.py:171} INFO - Processing /opt/airflow/dags/example_api_to_postgre/api_midway_to_postgres_dag.py took 0.057 seconds
[2022-02-12 14:21:34,820] {processor.py:163} INFO - Started process (PID=1746) to work on /opt/airflow/dags/example_api_to_postgre/api_midway_to_postgres_dag.py
[2022-02-12 14:21:34,822] {processor.py:625} INFO - Processing file /opt/airflow/dags/example_api_to_postgre/api_midway_to_postgres_dag.py for tasks to queue
[2022-02-12 14:21:34,823] {logging_mixin.py:109} INFO - [2022-02-12 14:21:34,823] {dagbag.py:500} INFO - Filling up the DagBag from /opt/airflow/dags/example_api_to_postgre/api_midway_to_postgres_dag.py
[2022-02-12 14:21:34,857] {logging_mixin.py:109} INFO - [2022-02-12 14:21:34,855] {dagbag.py:334} ERROR - Failed to import: /opt/airflow/dags/example_api_to_postgre/api_midway_to_postgres_dag.py
Traceback (most recent call last):
  File "/home/airflow/.local/lib/python3.7/site-packages/airflow/models/dagbag.py", line 331, in _load_modules_from_file
    loader.exec_module(new_module)
  File "<frozen importlib._bootstrap_external>", line 728, in exec_module
  File "<frozen importlib._bootstrap>", line 219, in _call_with_frames_removed
  File "/opt/airflow/dags/example_api_to_postgre/api_midway_to_postgres_dag.py", line 25, in <module>
    '--connection %s' % Variable.get("data_dev_connection")
  File "/home/airflow/.local/lib/python3.7/site-packages/airflow/models/variable.py", line 140, in get
    raise KeyError(f'Variable {key} does not exist')
KeyError: 'Variable data_dev_connection does not exist'
[2022-02-12 14:21:34,862] {processor.py:639} WARNING - No viable dags retrieved from /opt/airflow/dags/example_api_to_postgre/api_midway_to_postgres_dag.py
[2022-02-12 14:21:34,869] {processor.py:171} INFO - Processing /opt/airflow/dags/example_api_to_postgre/api_midway_to_postgres_dag.py took 0.052 seconds
[2022-02-12 14:22:05,252] {processor.py:163} INFO - Started process (PID=1798) to work on /opt/airflow/dags/example_api_to_postgre/api_midway_to_postgres_dag.py
[2022-02-12 14:22:05,254] {processor.py:625} INFO - Processing file /opt/airflow/dags/example_api_to_postgre/api_midway_to_postgres_dag.py for tasks to queue
[2022-02-12 14:22:05,256] {logging_mixin.py:109} INFO - [2022-02-12 14:22:05,256] {dagbag.py:500} INFO - Filling up the DagBag from /opt/airflow/dags/example_api_to_postgre/api_midway_to_postgres_dag.py
[2022-02-12 14:22:05,324] {logging_mixin.py:109} INFO - [2022-02-12 14:22:05,322] {dagbag.py:334} ERROR - Failed to import: /opt/airflow/dags/example_api_to_postgre/api_midway_to_postgres_dag.py
Traceback (most recent call last):
  File "/home/airflow/.local/lib/python3.7/site-packages/airflow/models/dagbag.py", line 331, in _load_modules_from_file
    loader.exec_module(new_module)
  File "<frozen importlib._bootstrap_external>", line 728, in exec_module
  File "<frozen importlib._bootstrap>", line 219, in _call_with_frames_removed
  File "/opt/airflow/dags/example_api_to_postgre/api_midway_to_postgres_dag.py", line 25, in <module>
    '--connection %s' % Variable.get("data_dev_connection")
  File "/home/airflow/.local/lib/python3.7/site-packages/airflow/models/variable.py", line 140, in get
    raise KeyError(f'Variable {key} does not exist')
KeyError: 'Variable data_dev_connection does not exist'
[2022-02-12 14:22:05,333] {processor.py:639} WARNING - No viable dags retrieved from /opt/airflow/dags/example_api_to_postgre/api_midway_to_postgres_dag.py
[2022-02-12 14:22:05,355] {processor.py:171} INFO - Processing /opt/airflow/dags/example_api_to_postgre/api_midway_to_postgres_dag.py took 0.109 seconds
[2022-02-12 14:22:35,477] {processor.py:163} INFO - Started process (PID=1836) to work on /opt/airflow/dags/example_api_to_postgre/api_midway_to_postgres_dag.py
[2022-02-12 14:22:35,479] {processor.py:625} INFO - Processing file /opt/airflow/dags/example_api_to_postgre/api_midway_to_postgres_dag.py for tasks to queue
[2022-02-12 14:22:35,482] {logging_mixin.py:109} INFO - [2022-02-12 14:22:35,481] {dagbag.py:500} INFO - Filling up the DagBag from /opt/airflow/dags/example_api_to_postgre/api_midway_to_postgres_dag.py
[2022-02-12 14:22:35,526] {logging_mixin.py:109} INFO - [2022-02-12 14:22:35,524] {dagbag.py:334} ERROR - Failed to import: /opt/airflow/dags/example_api_to_postgre/api_midway_to_postgres_dag.py
Traceback (most recent call last):
  File "/home/airflow/.local/lib/python3.7/site-packages/airflow/models/dagbag.py", line 331, in _load_modules_from_file
    loader.exec_module(new_module)
  File "<frozen importlib._bootstrap_external>", line 728, in exec_module
  File "<frozen importlib._bootstrap>", line 219, in _call_with_frames_removed
  File "/opt/airflow/dags/example_api_to_postgre/api_midway_to_postgres_dag.py", line 25, in <module>
    '--connection %s' % Variable.get("data_dev_connection")
  File "/home/airflow/.local/lib/python3.7/site-packages/airflow/models/variable.py", line 140, in get
    raise KeyError(f'Variable {key} does not exist')
KeyError: 'Variable data_dev_connection does not exist'
[2022-02-12 14:22:35,533] {processor.py:639} WARNING - No viable dags retrieved from /opt/airflow/dags/example_api_to_postgre/api_midway_to_postgres_dag.py
[2022-02-12 14:22:35,542] {processor.py:171} INFO - Processing /opt/airflow/dags/example_api_to_postgre/api_midway_to_postgres_dag.py took 0.068 seconds
[2022-02-12 14:23:06,448] {processor.py:163} INFO - Started process (PID=1880) to work on /opt/airflow/dags/example_api_to_postgre/api_midway_to_postgres_dag.py
[2022-02-12 14:23:06,450] {processor.py:625} INFO - Processing file /opt/airflow/dags/example_api_to_postgre/api_midway_to_postgres_dag.py for tasks to queue
[2022-02-12 14:23:06,452] {logging_mixin.py:109} INFO - [2022-02-12 14:23:06,451] {dagbag.py:500} INFO - Filling up the DagBag from /opt/airflow/dags/example_api_to_postgre/api_midway_to_postgres_dag.py
[2022-02-12 14:23:06,489] {logging_mixin.py:109} INFO - [2022-02-12 14:23:06,487] {dagbag.py:334} ERROR - Failed to import: /opt/airflow/dags/example_api_to_postgre/api_midway_to_postgres_dag.py
Traceback (most recent call last):
  File "/home/airflow/.local/lib/python3.7/site-packages/airflow/models/dagbag.py", line 331, in _load_modules_from_file
    loader.exec_module(new_module)
  File "<frozen importlib._bootstrap_external>", line 728, in exec_module
  File "<frozen importlib._bootstrap>", line 219, in _call_with_frames_removed
  File "/opt/airflow/dags/example_api_to_postgre/api_midway_to_postgres_dag.py", line 25, in <module>
    '--connection %s' % Variable.get("data_dev_connection")
  File "/home/airflow/.local/lib/python3.7/site-packages/airflow/models/variable.py", line 140, in get
    raise KeyError(f'Variable {key} does not exist')
KeyError: 'Variable data_dev_connection does not exist'
[2022-02-12 14:23:06,497] {processor.py:639} WARNING - No viable dags retrieved from /opt/airflow/dags/example_api_to_postgre/api_midway_to_postgres_dag.py
[2022-02-12 14:23:06,509] {processor.py:171} INFO - Processing /opt/airflow/dags/example_api_to_postgre/api_midway_to_postgres_dag.py took 0.066 seconds
[2022-02-12 14:23:36,812] {processor.py:163} INFO - Started process (PID=1926) to work on /opt/airflow/dags/example_api_to_postgre/api_midway_to_postgres_dag.py
[2022-02-12 14:23:36,817] {processor.py:625} INFO - Processing file /opt/airflow/dags/example_api_to_postgre/api_midway_to_postgres_dag.py for tasks to queue
[2022-02-12 14:23:36,818] {logging_mixin.py:109} INFO - [2022-02-12 14:23:36,818] {dagbag.py:500} INFO - Filling up the DagBag from /opt/airflow/dags/example_api_to_postgre/api_midway_to_postgres_dag.py
[2022-02-12 14:23:36,854] {logging_mixin.py:109} INFO - [2022-02-12 14:23:36,852] {dagbag.py:334} ERROR - Failed to import: /opt/airflow/dags/example_api_to_postgre/api_midway_to_postgres_dag.py
Traceback (most recent call last):
  File "/home/airflow/.local/lib/python3.7/site-packages/airflow/models/dagbag.py", line 331, in _load_modules_from_file
    loader.exec_module(new_module)
  File "<frozen importlib._bootstrap_external>", line 728, in exec_module
  File "<frozen importlib._bootstrap>", line 219, in _call_with_frames_removed
  File "/opt/airflow/dags/example_api_to_postgre/api_midway_to_postgres_dag.py", line 25, in <module>
    '--connection %s' % Variable.get("data_dev_connection")
  File "/home/airflow/.local/lib/python3.7/site-packages/airflow/models/variable.py", line 140, in get
    raise KeyError(f'Variable {key} does not exist')
KeyError: 'Variable data_dev_connection does not exist'
[2022-02-12 14:23:36,860] {processor.py:639} WARNING - No viable dags retrieved from /opt/airflow/dags/example_api_to_postgre/api_midway_to_postgres_dag.py
[2022-02-12 14:23:36,868] {processor.py:171} INFO - Processing /opt/airflow/dags/example_api_to_postgre/api_midway_to_postgres_dag.py took 0.063 seconds
[2022-02-12 14:24:07,080] {processor.py:163} INFO - Started process (PID=1970) to work on /opt/airflow/dags/example_api_to_postgre/api_midway_to_postgres_dag.py
[2022-02-12 14:24:07,085] {processor.py:625} INFO - Processing file /opt/airflow/dags/example_api_to_postgre/api_midway_to_postgres_dag.py for tasks to queue
[2022-02-12 14:24:07,087] {logging_mixin.py:109} INFO - [2022-02-12 14:24:07,087] {dagbag.py:500} INFO - Filling up the DagBag from /opt/airflow/dags/example_api_to_postgre/api_midway_to_postgres_dag.py
[2022-02-12 14:24:07,128] {logging_mixin.py:109} INFO - [2022-02-12 14:24:07,122] {dagbag.py:334} ERROR - Failed to import: /opt/airflow/dags/example_api_to_postgre/api_midway_to_postgres_dag.py
Traceback (most recent call last):
  File "/home/airflow/.local/lib/python3.7/site-packages/airflow/models/dagbag.py", line 331, in _load_modules_from_file
    loader.exec_module(new_module)
  File "<frozen importlib._bootstrap_external>", line 728, in exec_module
  File "<frozen importlib._bootstrap>", line 219, in _call_with_frames_removed
  File "/opt/airflow/dags/example_api_to_postgre/api_midway_to_postgres_dag.py", line 25, in <module>
    '--connection %s' % Variable.get("data_dev_connection")
  File "/home/airflow/.local/lib/python3.7/site-packages/airflow/models/variable.py", line 140, in get
    raise KeyError(f'Variable {key} does not exist')
KeyError: 'Variable data_dev_connection does not exist'
[2022-02-12 14:24:07,143] {processor.py:639} WARNING - No viable dags retrieved from /opt/airflow/dags/example_api_to_postgre/api_midway_to_postgres_dag.py
[2022-02-12 14:24:07,151] {processor.py:171} INFO - Processing /opt/airflow/dags/example_api_to_postgre/api_midway_to_postgres_dag.py took 0.075 seconds
[2022-02-12 14:24:37,831] {processor.py:163} INFO - Started process (PID=2024) to work on /opt/airflow/dags/example_api_to_postgre/api_midway_to_postgres_dag.py
[2022-02-12 14:24:37,835] {processor.py:625} INFO - Processing file /opt/airflow/dags/example_api_to_postgre/api_midway_to_postgres_dag.py for tasks to queue
[2022-02-12 14:24:37,836] {logging_mixin.py:109} INFO - [2022-02-12 14:24:37,836] {dagbag.py:500} INFO - Filling up the DagBag from /opt/airflow/dags/example_api_to_postgre/api_midway_to_postgres_dag.py
[2022-02-12 14:24:37,870] {logging_mixin.py:109} INFO - [2022-02-12 14:24:37,868] {dagbag.py:334} ERROR - Failed to import: /opt/airflow/dags/example_api_to_postgre/api_midway_to_postgres_dag.py
Traceback (most recent call last):
  File "/home/airflow/.local/lib/python3.7/site-packages/airflow/models/dagbag.py", line 331, in _load_modules_from_file
    loader.exec_module(new_module)
  File "<frozen importlib._bootstrap_external>", line 728, in exec_module
  File "<frozen importlib._bootstrap>", line 219, in _call_with_frames_removed
  File "/opt/airflow/dags/example_api_to_postgre/api_midway_to_postgres_dag.py", line 25, in <module>
    '--connection %s' % Variable.get("data_dev_connection")
  File "/home/airflow/.local/lib/python3.7/site-packages/airflow/models/variable.py", line 140, in get
    raise KeyError(f'Variable {key} does not exist')
KeyError: 'Variable data_dev_connection does not exist'
[2022-02-12 14:24:37,875] {processor.py:639} WARNING - No viable dags retrieved from /opt/airflow/dags/example_api_to_postgre/api_midway_to_postgres_dag.py
[2022-02-12 14:24:37,883] {processor.py:171} INFO - Processing /opt/airflow/dags/example_api_to_postgre/api_midway_to_postgres_dag.py took 0.057 seconds
[2022-02-12 14:25:08,581] {processor.py:163} INFO - Started process (PID=2079) to work on /opt/airflow/dags/example_api_to_postgre/api_midway_to_postgres_dag.py
[2022-02-12 14:25:08,584] {processor.py:625} INFO - Processing file /opt/airflow/dags/example_api_to_postgre/api_midway_to_postgres_dag.py for tasks to queue
[2022-02-12 14:25:08,586] {logging_mixin.py:109} INFO - [2022-02-12 14:25:08,586] {dagbag.py:500} INFO - Filling up the DagBag from /opt/airflow/dags/example_api_to_postgre/api_midway_to_postgres_dag.py
[2022-02-12 14:25:08,645] {logging_mixin.py:109} INFO - [2022-02-12 14:25:08,643] {dagbag.py:334} ERROR - Failed to import: /opt/airflow/dags/example_api_to_postgre/api_midway_to_postgres_dag.py
Traceback (most recent call last):
  File "/home/airflow/.local/lib/python3.7/site-packages/airflow/models/dagbag.py", line 331, in _load_modules_from_file
    loader.exec_module(new_module)
  File "<frozen importlib._bootstrap_external>", line 728, in exec_module
  File "<frozen importlib._bootstrap>", line 219, in _call_with_frames_removed
  File "/opt/airflow/dags/example_api_to_postgre/api_midway_to_postgres_dag.py", line 25, in <module>
    '--connection %s' % Variable.get("data_dev_connection")
  File "/home/airflow/.local/lib/python3.7/site-packages/airflow/models/variable.py", line 140, in get
    raise KeyError(f'Variable {key} does not exist')
KeyError: 'Variable data_dev_connection does not exist'
[2022-02-12 14:25:08,651] {processor.py:639} WARNING - No viable dags retrieved from /opt/airflow/dags/example_api_to_postgre/api_midway_to_postgres_dag.py
[2022-02-12 14:25:08,660] {processor.py:171} INFO - Processing /opt/airflow/dags/example_api_to_postgre/api_midway_to_postgres_dag.py took 0.083 seconds
[2022-02-12 14:25:38,695] {processor.py:163} INFO - Started process (PID=2123) to work on /opt/airflow/dags/example_api_to_postgre/api_midway_to_postgres_dag.py
[2022-02-12 14:25:38,697] {processor.py:625} INFO - Processing file /opt/airflow/dags/example_api_to_postgre/api_midway_to_postgres_dag.py for tasks to queue
[2022-02-12 14:25:38,699] {logging_mixin.py:109} INFO - [2022-02-12 14:25:38,699] {dagbag.py:500} INFO - Filling up the DagBag from /opt/airflow/dags/example_api_to_postgre/api_midway_to_postgres_dag.py
[2022-02-12 14:25:38,734] {logging_mixin.py:109} INFO - [2022-02-12 14:25:38,732] {dagbag.py:334} ERROR - Failed to import: /opt/airflow/dags/example_api_to_postgre/api_midway_to_postgres_dag.py
Traceback (most recent call last):
  File "/home/airflow/.local/lib/python3.7/site-packages/airflow/models/dagbag.py", line 331, in _load_modules_from_file
    loader.exec_module(new_module)
  File "<frozen importlib._bootstrap_external>", line 728, in exec_module
  File "<frozen importlib._bootstrap>", line 219, in _call_with_frames_removed
  File "/opt/airflow/dags/example_api_to_postgre/api_midway_to_postgres_dag.py", line 25, in <module>
    '--connection %s' % Variable.get("data_dev_connection")
  File "/home/airflow/.local/lib/python3.7/site-packages/airflow/models/variable.py", line 140, in get
    raise KeyError(f'Variable {key} does not exist')
KeyError: 'Variable data_dev_connection does not exist'
[2022-02-12 14:25:38,740] {processor.py:639} WARNING - No viable dags retrieved from /opt/airflow/dags/example_api_to_postgre/api_midway_to_postgres_dag.py
[2022-02-12 14:25:38,747] {processor.py:171} INFO - Processing /opt/airflow/dags/example_api_to_postgre/api_midway_to_postgres_dag.py took 0.056 seconds
[2022-02-12 14:26:08,785] {processor.py:163} INFO - Started process (PID=2160) to work on /opt/airflow/dags/example_api_to_postgre/api_midway_to_postgres_dag.py
[2022-02-12 14:26:08,789] {processor.py:625} INFO - Processing file /opt/airflow/dags/example_api_to_postgre/api_midway_to_postgres_dag.py for tasks to queue
[2022-02-12 14:26:08,791] {logging_mixin.py:109} INFO - [2022-02-12 14:26:08,791] {dagbag.py:500} INFO - Filling up the DagBag from /opt/airflow/dags/example_api_to_postgre/api_midway_to_postgres_dag.py
[2022-02-12 14:26:08,839] {logging_mixin.py:109} INFO - [2022-02-12 14:26:08,837] {dagbag.py:334} ERROR - Failed to import: /opt/airflow/dags/example_api_to_postgre/api_midway_to_postgres_dag.py
Traceback (most recent call last):
  File "/home/airflow/.local/lib/python3.7/site-packages/airflow/models/dagbag.py", line 331, in _load_modules_from_file
    loader.exec_module(new_module)
  File "<frozen importlib._bootstrap_external>", line 728, in exec_module
  File "<frozen importlib._bootstrap>", line 219, in _call_with_frames_removed
  File "/opt/airflow/dags/example_api_to_postgre/api_midway_to_postgres_dag.py", line 25, in <module>
    '--connection %s' % Variable.get("data_dev_connection")
  File "/home/airflow/.local/lib/python3.7/site-packages/airflow/models/variable.py", line 140, in get
    raise KeyError(f'Variable {key} does not exist')
KeyError: 'Variable data_dev_connection does not exist'
[2022-02-12 14:26:08,846] {processor.py:639} WARNING - No viable dags retrieved from /opt/airflow/dags/example_api_to_postgre/api_midway_to_postgres_dag.py
[2022-02-12 14:26:08,854] {processor.py:171} INFO - Processing /opt/airflow/dags/example_api_to_postgre/api_midway_to_postgres_dag.py took 0.075 seconds
[2022-02-12 14:26:39,808] {processor.py:163} INFO - Started process (PID=2215) to work on /opt/airflow/dags/example_api_to_postgre/api_midway_to_postgres_dag.py
[2022-02-12 14:26:39,812] {processor.py:625} INFO - Processing file /opt/airflow/dags/example_api_to_postgre/api_midway_to_postgres_dag.py for tasks to queue
[2022-02-12 14:26:39,814] {logging_mixin.py:109} INFO - [2022-02-12 14:26:39,814] {dagbag.py:500} INFO - Filling up the DagBag from /opt/airflow/dags/example_api_to_postgre/api_midway_to_postgres_dag.py
[2022-02-12 14:26:39,872] {logging_mixin.py:109} INFO - [2022-02-12 14:26:39,868] {dagbag.py:334} ERROR - Failed to import: /opt/airflow/dags/example_api_to_postgre/api_midway_to_postgres_dag.py
Traceback (most recent call last):
  File "/home/airflow/.local/lib/python3.7/site-packages/airflow/models/dagbag.py", line 331, in _load_modules_from_file
    loader.exec_module(new_module)
  File "<frozen importlib._bootstrap_external>", line 728, in exec_module
  File "<frozen importlib._bootstrap>", line 219, in _call_with_frames_removed
  File "/opt/airflow/dags/example_api_to_postgre/api_midway_to_postgres_dag.py", line 25, in <module>
    '--connection %s' % Variable.get("data_dev_connection")
  File "/home/airflow/.local/lib/python3.7/site-packages/airflow/models/variable.py", line 140, in get
    raise KeyError(f'Variable {key} does not exist')
KeyError: 'Variable data_dev_connection does not exist'
[2022-02-12 14:26:39,883] {processor.py:639} WARNING - No viable dags retrieved from /opt/airflow/dags/example_api_to_postgre/api_midway_to_postgres_dag.py
[2022-02-12 14:26:39,906] {processor.py:171} INFO - Processing /opt/airflow/dags/example_api_to_postgre/api_midway_to_postgres_dag.py took 0.093 seconds
[2022-02-12 14:27:10,484] {processor.py:163} INFO - Started process (PID=2258) to work on /opt/airflow/dags/example_api_to_postgre/api_midway_to_postgres_dag.py
[2022-02-12 14:27:10,488] {processor.py:625} INFO - Processing file /opt/airflow/dags/example_api_to_postgre/api_midway_to_postgres_dag.py for tasks to queue
[2022-02-12 14:27:10,490] {logging_mixin.py:109} INFO - [2022-02-12 14:27:10,490] {dagbag.py:500} INFO - Filling up the DagBag from /opt/airflow/dags/example_api_to_postgre/api_midway_to_postgres_dag.py
[2022-02-12 14:27:10,534] {logging_mixin.py:109} INFO - [2022-02-12 14:27:10,531] {dagbag.py:334} ERROR - Failed to import: /opt/airflow/dags/example_api_to_postgre/api_midway_to_postgres_dag.py
Traceback (most recent call last):
  File "/home/airflow/.local/lib/python3.7/site-packages/airflow/models/dagbag.py", line 331, in _load_modules_from_file
    loader.exec_module(new_module)
  File "<frozen importlib._bootstrap_external>", line 728, in exec_module
  File "<frozen importlib._bootstrap>", line 219, in _call_with_frames_removed
  File "/opt/airflow/dags/example_api_to_postgre/api_midway_to_postgres_dag.py", line 25, in <module>
    '--connection %s' % Variable.get("data_dev_connection")
  File "/home/airflow/.local/lib/python3.7/site-packages/airflow/models/variable.py", line 140, in get
    raise KeyError(f'Variable {key} does not exist')
KeyError: 'Variable data_dev_connection does not exist'
[2022-02-12 14:27:10,545] {processor.py:639} WARNING - No viable dags retrieved from /opt/airflow/dags/example_api_to_postgre/api_midway_to_postgres_dag.py
[2022-02-12 14:27:10,557] {processor.py:171} INFO - Processing /opt/airflow/dags/example_api_to_postgre/api_midway_to_postgres_dag.py took 0.079 seconds
[2022-02-12 14:27:40,753] {processor.py:163} INFO - Started process (PID=2322) to work on /opt/airflow/dags/example_api_to_postgre/api_midway_to_postgres_dag.py
[2022-02-12 14:27:40,756] {processor.py:625} INFO - Processing file /opt/airflow/dags/example_api_to_postgre/api_midway_to_postgres_dag.py for tasks to queue
[2022-02-12 14:27:40,758] {logging_mixin.py:109} INFO - [2022-02-12 14:27:40,758] {dagbag.py:500} INFO - Filling up the DagBag from /opt/airflow/dags/example_api_to_postgre/api_midway_to_postgres_dag.py
[2022-02-12 14:27:40,792] {logging_mixin.py:109} INFO - [2022-02-12 14:27:40,790] {dagbag.py:334} ERROR - Failed to import: /opt/airflow/dags/example_api_to_postgre/api_midway_to_postgres_dag.py
Traceback (most recent call last):
  File "/home/airflow/.local/lib/python3.7/site-packages/airflow/models/dagbag.py", line 331, in _load_modules_from_file
    loader.exec_module(new_module)
  File "<frozen importlib._bootstrap_external>", line 728, in exec_module
  File "<frozen importlib._bootstrap>", line 219, in _call_with_frames_removed
  File "/opt/airflow/dags/example_api_to_postgre/api_midway_to_postgres_dag.py", line 25, in <module>
    '--connection %s' % Variable.get("data_dev_connection")
  File "/home/airflow/.local/lib/python3.7/site-packages/airflow/models/variable.py", line 140, in get
    raise KeyError(f'Variable {key} does not exist')
KeyError: 'Variable data_dev_connection does not exist'
[2022-02-12 14:27:40,797] {processor.py:639} WARNING - No viable dags retrieved from /opt/airflow/dags/example_api_to_postgre/api_midway_to_postgres_dag.py
[2022-02-12 14:27:40,804] {processor.py:171} INFO - Processing /opt/airflow/dags/example_api_to_postgre/api_midway_to_postgres_dag.py took 0.060 seconds
[2022-02-12 14:28:11,260] {processor.py:163} INFO - Started process (PID=2388) to work on /opt/airflow/dags/example_api_to_postgre/api_midway_to_postgres_dag.py
[2022-02-12 14:28:11,263] {processor.py:625} INFO - Processing file /opt/airflow/dags/example_api_to_postgre/api_midway_to_postgres_dag.py for tasks to queue
[2022-02-12 14:28:11,267] {logging_mixin.py:109} INFO - [2022-02-12 14:28:11,267] {dagbag.py:500} INFO - Filling up the DagBag from /opt/airflow/dags/example_api_to_postgre/api_midway_to_postgres_dag.py
[2022-02-12 14:28:11,312] {logging_mixin.py:109} INFO - [2022-02-12 14:28:11,309] {dagbag.py:334} ERROR - Failed to import: /opt/airflow/dags/example_api_to_postgre/api_midway_to_postgres_dag.py
Traceback (most recent call last):
  File "/home/airflow/.local/lib/python3.7/site-packages/airflow/models/dagbag.py", line 331, in _load_modules_from_file
    loader.exec_module(new_module)
  File "<frozen importlib._bootstrap_external>", line 728, in exec_module
  File "<frozen importlib._bootstrap>", line 219, in _call_with_frames_removed
  File "/opt/airflow/dags/example_api_to_postgre/api_midway_to_postgres_dag.py", line 25, in <module>
    '--connection %s' % Variable.get("data_dev_connection")
  File "/home/airflow/.local/lib/python3.7/site-packages/airflow/models/variable.py", line 140, in get
    raise KeyError(f'Variable {key} does not exist')
KeyError: 'Variable data_dev_connection does not exist'
[2022-02-12 14:28:11,327] {processor.py:639} WARNING - No viable dags retrieved from /opt/airflow/dags/example_api_to_postgre/api_midway_to_postgres_dag.py
[2022-02-12 14:28:11,340] {processor.py:171} INFO - Processing /opt/airflow/dags/example_api_to_postgre/api_midway_to_postgres_dag.py took 0.092 seconds
[2022-02-12 14:28:41,481] {processor.py:163} INFO - Started process (PID=2434) to work on /opt/airflow/dags/example_api_to_postgre/api_midway_to_postgres_dag.py
[2022-02-12 14:28:41,484] {processor.py:625} INFO - Processing file /opt/airflow/dags/example_api_to_postgre/api_midway_to_postgres_dag.py for tasks to queue
[2022-02-12 14:28:41,487] {logging_mixin.py:109} INFO - [2022-02-12 14:28:41,486] {dagbag.py:500} INFO - Filling up the DagBag from /opt/airflow/dags/example_api_to_postgre/api_midway_to_postgres_dag.py
[2022-02-12 14:28:41,588] {logging_mixin.py:109} INFO - [2022-02-12 14:28:41,538] {dagbag.py:334} ERROR - Failed to import: /opt/airflow/dags/example_api_to_postgre/api_midway_to_postgres_dag.py
Traceback (most recent call last):
  File "/home/airflow/.local/lib/python3.7/site-packages/airflow/models/dagbag.py", line 331, in _load_modules_from_file
    loader.exec_module(new_module)
  File "<frozen importlib._bootstrap_external>", line 728, in exec_module
  File "<frozen importlib._bootstrap>", line 219, in _call_with_frames_removed
  File "/opt/airflow/dags/example_api_to_postgre/api_midway_to_postgres_dag.py", line 25, in <module>
    '--connection %s' % Variable.get("data_dev_connection")
  File "/home/airflow/.local/lib/python3.7/site-packages/airflow/models/variable.py", line 140, in get
    raise KeyError(f'Variable {key} does not exist')
KeyError: 'Variable data_dev_connection does not exist'
[2022-02-12 14:28:41,598] {processor.py:639} WARNING - No viable dags retrieved from /opt/airflow/dags/example_api_to_postgre/api_midway_to_postgres_dag.py
[2022-02-12 14:28:41,610] {processor.py:171} INFO - Processing /opt/airflow/dags/example_api_to_postgre/api_midway_to_postgres_dag.py took 0.136 seconds
